Workbook
Name DashboardMonths: 'Dashboard Engine'!$B$3:$B$14
Name QuickPeriods: 'Dashboard Engine'!$Z$2:$Z$8
Name SegmentaçãodeDados_Auto_Renewal: #N/A
Name SegmentaçãodeDados_EA_Play_Season_Pass: #N/A
Name SegmentaçãodeDados_Minecraft_Season_Pass: #N/A
Name SegmentaçãodeDados_Plan: #N/A
Name SegmentaçãodeDados_Subscription_Type: #N/A

Sheet Instruções
A1: XBOX | C1: GUIA DE UTILIZAÇÃO
C5: Como explorar o dashboard de assinaturas Xbox Game Pass
C8: 1 ESCOLHA O PERÍODO | G8: 2 COMBINE OS FILTROS
C10: Na barra lateral do Dashboard, escolha Ano completo, um semestre ou um trimestre. Os cartões e gráficos serão recalculados automaticamente. | G10: Use Plano, Renovação, Periodicidade, EA Play e Minecraft em conjunto para comparar segmentos específicos.
C15: 3 LEIA OS CARTÕES | G15: 4 EXPLORE OS GRÁFICOS
C17: Receita, Assinantes, Cupons e Renovação mostram o resultado do período selecionado e a variação contra o período anterior equivalente. | G17: Analise faturamento anual, renovação, passes, planos, evolução mensal e impacto dos cupons com os mesmos filtros.
C22: PASSO A PASSO
C24: 1. Abra a aba D̳ashboard.
C26: 2. Selecione o período no primeiro controle da barra lateral.
C28: 3. Aplique um ou mais filtros categóricos para comparar segmentos.
C30: 4. Use o ícone de limpar filtro em cada segmentação para voltar à visão completa.
A32: D̳ASHBOARD
C33: DICAS IMPORTANTES
C35: • Para comparar categorias, altere um filtro por vez e observe cartões e gráficos. • Combinações sem registros aparecem como “SEM DADOS”. • O período anterior é calculado automaticamente com a mesma duração.

Sheet A̳ssets
B3: Paleta de Cores
B5: # 9BC848 | C5: Xbox Color | E5: # E8E6E9 | F5: negative zone
B6: # 22C55E | C6: Xbox Color
B7: # 2AE6B1 | C7: Menus
B8: # 5BF6A8 | C8: Menus
B12: Logos | J12: ícones

Sheet B̳ases
A1: Subscriber ID | B1: Name | C1: Plan | D1: Start Date | E1: Auto Renewal | F1: Subscription Price | G1: Subscription Type | H1: EA Play Season Pass | I1: EA Play Season Pass Price | J1: Minecraft Season Pass | K1: Minecraft Season Pass Price | L1: Coupon Value | M1: Total Value | N1: Month Start | O1: Year
A2: 3231 | B2: João Silva | C2: Ultimate | D2: 45292 | E2: Yes | F2: 15 | G2: Monthly | H2: Yes | I2: 30 | J2: Yes | K2: 20 | L2: 5 | M2: 60 | N2: =DATE(YEAR(Tabela1[[#This Row],[Start Date]]),MONTH(Tabela1[[#This Row],[Start Date]]),1) -> 45292 | O2: =YEAR(Tabela1[[#This Row],[Start Date]]) -> 2024
A3: 3232 | B3: Maria Oliveira | C3: Core | D3: 45306 | E3: No | F3: 5 | G3: Annual | H3: No | I3: - | J3: No | K3: 0 | L3: 0 | M3: 5 | N3: =DATE(YEAR(Tabela1[[#This Row],[Start Date]]),MONTH(Tabela1[[#This Row],[Start Date]]),1) -> 45292 | O3: =YEAR(Tabela1[[#This Row],[Start Date]]) -> 2024
A4: 3233 | B4: Lucas Fernandes | C4: Standard | D4: 45332 | E4: Yes | F4: 10 | G4: Quarterly | H4: No | I4: - | J4: Yes | K4: 20 | L4: 10 | M4: 20 | N4: =DATE(YEAR(Tabela1[[#This Row],[Start Date]]),MONTH(Tabela1[[#This Row],[Start Date]]),1) -> 45323 | O4: =YEAR(Tabela1[[#This Row],[Start Date]]) -> 2024
A5: 3234 | B5: Ana Souza | C5: Ultimate | D5: 45342 | E5: No | F5: 15 | G5: Monthly | H5: Yes | I5: 30 | J5: Yes | K5: 20 | L5: 3 | M5: 62 | N5: =DATE(YEAR(Tabela1[[#This Row],[Start Date]]),MONTH(Tabela1[[#This Row],[Start Date]]),1) -> 45323 | O5: =YEAR(Tabela1[[#This Row],[Start Date]]) -> 2024
A6: 3235 | B6: Pedro Gonçalves | C6: Core | D6: 45356 | E6: Yes | F6: 5 | G6: Monthly | H6: No | I6: - | J6: No | K6: 0 | L6: 1 | M6: 4 | N6: =DATE(YEAR(Tabela1[[#This Row],[Start Date]]),MONTH(Tabela1[[#This Row],[Start Date]]),1) -> 45352 | O6: =YEAR(Tabela1[[#This Row],[Start Date]]) -> 2024
A7: 3236 | B7: Felipe Costa | C7: Standard | D7: 45353 | E7: No | F7: 10 | G7: Monthly | H7: No | I7: - | J7: Yes | K7: 20 | L7: 2 | M7: 28 | N7: =DATE(YEAR(Tabela1[[#This Row],[Start Date]]),MONTH(Tabela1[[#This Row],[Start Date]]),1) -> 45352 | O7: =YEAR(Tabela1[[#This Row],[Start Date]]) -> 2024
A8: 3237 | B8: Camila Ribeiro | C8: Ultimate | D8: 45354 | E8: Yes | F8: 15 | G8: Quarterly | H8: Yes | I8: 30 | J8: Yes | K8: 20 | L8: 10 | M8: 55 | N8: =DATE(YEAR(Tabela1[[#This Row],[Start Date]]),MONTH(Tabela1[[#This Row],[Start Date]]),1) -> 45352 | O8: =YEAR(Tabela1[[#This Row],[Start Date]]) -> 2024
A9: 3238 | B9: André Mendes | C9: Core | D9: 45355 | E9: Yes | F9: 5 | G9: Annual | H9: No | I9: - | J9: No | K9: 0 | L9: 0 | M9: 5 | N9: =DATE(YEAR(Tabela1[[#This Row],[Start Date]]),MONTH(Tabela1[[#This Row],[Start Date]]),1) -> 45352 | O9: =YEAR(Tabela1[[#This Row],[Start Date]]) -> 2024
A10: 3239 | B10: Sofia Almeida | C10: Ultimate | D10: 45356 | E10: No | F10: 15 | G10: Monthly | H10: Yes | I10: 30 | J10: Yes | K10: 20 | L10: 5 | M10: 60 | N10: =DATE(YEAR(Tabela1[[#This Row],[Start Date]]),MONTH(Tabela1[[#This Row],[Start Date]]),1) -> 45352 | O10: =YEAR(Tabela1[[#This Row],[Start Date]]) -> 2024
A11: 3240 | B11: Bruno Martins | C11: Standard | D11: 45357 | E11: Yes | F11: 10 | G11: Quarterly | H11: No | I11: - | J11: Yes | K11: 20 | L11: 15 | M11: 15 | N11: =DATE(YEAR(Tabela1[[#This Row],[Start Date]]),MONTH(Tabela1[[#This Row],[Start Date]]),1) -> 45352 | O11: =YEAR(Tabela1[[#This Row],[Start Date]]) -> 2024
A12: 3241 | B12: Rita Castro | C12: Core | D12: 45358 | E12: No | F12: 5 | G12: Monthly | H12: No | I12: - | J12: No | K12: 0 | L12: 1 | M12: 4 | N12: =DATE(YEAR(Tabela1[[#This Row],[Start Date]]),MONTH(Tabela1[[#This Row],[Start Date]]),1) -> 45352 | O12: =YEAR(Tabela1[[#This Row],[Start Date]]) -> 2024
A13: 3242 | B13: Marco Túlio | C13: Ultimate | D13: 45359 | E13: Yes | F13: 15 | G13: Annual | H13: Yes | I13: 30 | J13: Yes | K13: 20 | L13: 20 | M13: 45 | N13: =DATE(YEAR(Tabela1[[#This Row],[Start Date]]),MONTH(Tabela1[[#This Row],[Start Date]]),1) -> 45352 | O13: =YEAR(Tabela1[[#This Row],[Start Date]]) -> 2024
A14: 3243 | B14: Lívia Silveira | C14: Standard | D14: 45360 | E14: No | F14: 10 | G14: Monthly | H14: No | I14: - | J14: Yes | K14: 20 | L14: 10 | M14: 20 | N14: =DATE(YEAR(Tabela1[[#This Row],[Start Date]]),MONTH(Tabela1[[#This Row],[Start Date]]),1) -> 45352 | O14: =YEAR(Tabela1[[#This Row],[Start Date]]) -> 2024
A15: 3244 | B15: Diogo Sousa | C15: Core | D15: 45361 | E15: Yes | F15: 5 | G15: Quarterly | H15: No | I15: - | J15: No | K15: 0 | L15: 0 | M15: 5 | N15: =DATE(YEAR(Tabela1[[#This Row],[Start Date]]),MONTH(Tabela1[[#This Row],[Start Date]]),1) -> 45352 | O15: =YEAR(Tabela1[[#This Row],[Start Date]]) -> 2024
A16: 3245 | B16: Fernanda Lima | C16: Ultimate | D16: 45362 | E16: No | F16: 15 | G16: Monthly | H16: Yes | I16: 30 | J16: Yes | K16: 20 | L16: 8 | M16: 57 | N16: =DATE(YEAR(Tabela1[[#This Row],[Start Date]]),MONTH(Tabela1[[#This Row],[Start Date]]),1) -> 45352 | O16: =YEAR(Tabela1[[#This Row],[Start Date]]) -> 2024
A17: 3246 | B17: Caio Pereira | C17: Standard | D17: 45363 | E17: Yes | F17: 10 | G17: Annual | H17: No | I17: - | J17: Yes | K17: 20 | L17: 12 | M17: 18 | N17: =DATE(YEAR(Tabela1[[#This Row],[Start Date]]),MONTH(Tabela1[[#This Row],[Start Date]]),1) -> 45352 | O17: =YEAR(Tabela1[[#This Row],[Start Date]]) -> 2024
A18: 3247 | B18: Beatriz Gomes | C18: Core | D18: 45364 | E18: No | F18: 5 | G18: Monthly | H18: No | I18: - | J18: No | K18: 0 | L18: 2 | M18: 3 | N18: =DATE(YEAR(Tabela1[[#This Row],[Start Date]]),MONTH(Tabela1[[#This Row],[Start Date]]),1) -> 45352 | O18: =YEAR(Tabela1[[#This Row],[Start Date]]) -> 2024
A19: 3248 | B19: Cesar Oliveira | C19: Ultimate | D19: 45365 | E19: Yes | F19: 15 | G19: Quarterly | H19: Yes | I19: 30 | J19: Yes | K19: 20 | L19: 7 | M19: 58 | N19: =DATE(YEAR(Tabela1[[#This Row],[Start Date]]),MONTH(Tabela1[[#This Row],[Start Date]]),1) -> 45352 | O19: =YEAR(Tabela1[[#This Row],[Start Date]]) -> 2024
A20: 3249 | B20: Débora Machado | C20: Standard | D20: 45366 | E20: No | F20: 10 | G20: Monthly | H20: No | I20: - | J20: Yes | K20: 20 | L20: 5 | M20: 25 | N20: =DATE(YEAR(Tabela1[[#This Row],[Start Date]]),MONTH(Tabela1[[#This Row],[Start Date]]),1) -> 45352 | O20: =YEAR(Tabela1[[#This Row],[Start Date]]) -> 2024
A21: 3250 | B21: Eduardo Vargas | C21: Core | D21: 45367 | E21: Yes | F21: 5 | G21: Annual | H21: No | I21: - | J21: No | K21: 0 | L21: 0 | M21: 5 | N21: =DATE(YEAR(Tabela1[[#This Row],[Start Date]]),MONTH(Tabela1[[#This Row],[Start Date]]),1) -> 45352 | O21: =YEAR(Tabela1[[#This Row],[Start Date]]) -> 2024
A22: 3251 | B22: Gabriela Santos | C22: Ultimate | D22: 45368 | E22: No | F22: 15 | G22: Monthly | H22: Yes | I22: 30 | J22: Yes | K22: 20 | L22: 3 | M22: 62 | N22: =DATE(YEAR(Tabela1[[#This Row],[Start Date]]),MONTH(Tabela1[[#This Row],[Start Date]]),1) -> 45352 | O22: =YEAR(Tabela1[[#This Row],[Start Date]]) -> 2024
A23: 3252 | B23: Henrique Dias | C23: Standard | D23: 45369 | E23: Yes | F23: 10 | G23: Quarterly | H23: No | I23: - | J23: Yes | K23: 20 | L23: 15 | M23: 15 | N23: =DATE(YEAR(Tabela1[[#This Row],[Start Date]]),MONTH(Tabela1[[#This Row],[Start Date]]),1) -> 45352 | O23: =YEAR(Tabela1[[#This Row],[Start Date]]) -> 2024
A24: 3253 | B24: Isabela Moreira | C24: Core | D24: 45370 | E24: No | F24: 5 | G24: Monthly | H24: No | I24: - | J24: No | K24: 0 | L24: 1 | M24: 4 | N24: =DATE(YEAR(Tabela1[[#This Row],[Start Date]]),MONTH(Tabela1[[#This Row],[Start Date]]),1) -> 45352 | O24: =YEAR(Tabela1[[#This Row],[Start Date]]) -> 2024
A25: 3254 | B25: Joaquim Barbosa | C25: Ultimate | D25: 45371 | E25: Yes | F25: 15 | G25: Annual | H25: Yes | I25: 30 | J25: Yes | K25: 20 | L25: 20 | M25: 45 | N25: =DATE(YEAR(Tabela1[[#This Row],[Start Date]]),MONTH(Tabela1[[#This Row],[Start Date]]),1) -> 45352 | O25: =YEAR(Tabela1[[#This Row],[Start Date]]) -> 2024
A26: 3255 | B26: Lara Rocha | C26: Standard | D26: 45372 | E26: No | F26: 10 | G26: Monthly | H26: No | I26: - | J26: Yes | K26: 20 | L26: 10 | M26: 20 | N26: =DATE(YEAR(Tabela1[[#This Row],[Start Date]]),MONTH(Tabela1[[#This Row],[Start Date]]),1) -> 45352 | O26: =YEAR(Tabela1[[#This Row],[Start Date]]) -> 2024
A27: 3256 | B27: Matheus Silva | C27: Core | D27: 45373 | E27: Yes | F27: 5 | G27: Quarterly | H27: No | I27: - | J27: No | K27: 0 | L27: 0 | M27: 5 | N27: =DATE(YEAR(Tabela1[[#This Row],[Start Date]]),MONTH(Tabela1[[#This Row],[Start Date]]),1) -> 45352 | O27: =YEAR(Tabela1[[#This Row],[Start Date]]) -> 2024
A28: 3257 | B28: Nicole Costa | C28: Ultimate | D28: 45374 | E28: No | F28: 15 | G28: Monthly | H28: Yes | I28: 30 | J28: Yes | K28: 20 | L28: 5 | M28: 60 | N28: =DATE(YEAR(Tabela1[[#This Row],[Start Date]]),MONTH(Tabela1[[#This Row],[Start Date]]),1) -> 45352 | O28: =YEAR(Tabela1[[#This Row],[Start Date]]) -> 2024
A29: 3258 | B29: Otávio Mendonça | C29: Standard | D29: 45375 | E29: Yes | F29: 10 | G29: Annual | H29: No | I29: - | J29: Yes | K29: 20 | L29: 15 | M29: 15 | N29: =DATE(YEAR(Tabela1[[#This Row],[Start Date]]),MONTH(Tabela1[[#This Row],[Start Date]]),1) -> 45352 | O29: =YEAR(Tabela1[[#This Row],[Start Date]]) -> 2024
A30: 3259 | B30: Paula Ferreira | C30: Core | D30: 45376 | E30: No | F30: 5 | G30: Monthly | H30: No | I30: - | J30: No | K30: 0 | L30: 1 | M30: 4 | N30: =DATE(YEAR(Tabela1[[#This Row],[Start Date]]),MONTH(Tabela1[[#This Row],[Start Date]]),1) -> 45352 | O30: =YEAR(Tabela1[[#This Row],[Start Date]]) -> 2024
A31: 3260 | B31: Raquel Alves | C31: Ultimate | D31: 45377 | E31: Yes | F31: 15 | G31: Quarterly | H31: Yes | I31: 30 | J31: Yes | K31: 20 | L31: 7 | M31: 58 | N31: =DATE(YEAR(Tabela1[[#This Row],[Start Date]]),MONTH(Tabela1[[#This Row],[Start Date]]),1) -> 45352 | O31: =YEAR(Tabela1[[#This Row],[Start Date]]) -> 2024
A32: 3261 | B32: Samuel Pires | C32: Standard | D32: 45378 | E32: No | F32: 10 | G32: Monthly | H32: No | I32: - | J32: Yes | K32: 20 | L32: 10 | M32: 20 | N32: =DATE(YEAR(Tabela1[[#This Row],[Start Date]]),MONTH(Tabela1[[#This Row],[Start Date]]),1) -> 45352 | O32: =YEAR(Tabela1[[#This Row],[Start Date]]) -> 2024
A33: 3262 | B33: Tânia Barros | C33: Core | D33: 45379 | E33: Yes | F33: 5 | G33: Annual | H33: No | I33: - | J33: No | K33: 0 | L33: 0 | M33: 5 | N33: =DATE(YEAR(Tabela1[[#This Row],[Start Date]]),MONTH(Tabela1[[#This Row],[Start Date]]),1) -> 45352 | O33: =YEAR(Tabela1[[#This Row],[Start Date]]) -> 2024
A34: 3263 | B34: Vinicius Lima | C34: Ultimate | D34: 45380 | E34: No | F34: 15 | G34: Monthly | H34: Yes | I34: 30 | J34: Yes | K34: 20 | L34: 3 | M34: 62 | N34: =DATE(YEAR(Tabela1[[#This Row],[Start Date]]),MONTH(Tabela1[[#This Row],[Start Date]]),1) -> 45352 | O34: =YEAR(Tabela1[[#This Row],[Start Date]]) -> 2024
A35: 3264 | B35: Yasmin Teixeira | C35: Standard | D35: 45381 | E35: Yes | F35: 10 | G35: Quarterly | H35: No | I35: - | J35: Yes | K35: 20 | L35: 15 | M35: 15 | N35: =DATE(YEAR(Tabela1[[#This Row],[Start Date]]),MONTH(Tabela1[[#This Row],[Start Date]]),1) -> 45352 | O35: =YEAR(Tabela1[[#This Row],[Start Date]]) -> 2024
A36: 3265 | B36: Zé Carlos | C36: Core | D36: 45382 | E36: No | F36: 5 | G36: Monthly | H36: No | I36: - | J36: No | K36: 0 | L36: 1 | M36: 4 | N36: =DATE(YEAR(Tabela1[[#This Row],[Start Date]]),MONTH(Tabela1[[#This Row],[Start Date]]),1) -> 45352 | O36: =YEAR(Tabela1[[#This Row],[Start Date]]) -> 2024
A37: 3266 | B37: Amanda Nogueira | C37: Core | D37: 45383 | E37: Yes | F37: 5 | G37: Monthly | H37: No | I37: - | J37: No | K37: 0 | L37: 0 | M37: 5 | N37: =DATE(YEAR(Tabela1[[#This Row],[Start Date]]),MONTH(Tabela1[[#This Row],[Start Date]]),1) -> 45383 | O37: =YEAR(Tabela1[[#This Row],[Start Date]]) -> 2024
A38: 3267 | B38: Bruno Cavalheiro | C38: Ultimate | D38: 45384 | E38: No | F38: 15 | G38: Quarterly | H38: Yes | I38: 30 | J38: Yes | K38: 20 | L38: 7 | M38: 58 | N38: =DATE(YEAR(Tabela1[[#This Row],[Start Date]]),MONTH(Tabela1[[#This Row],[Start Date]]),1) -> 45383 | O38: =YEAR(Tabela1[[#This Row],[Start Date]]) -> 2024
A39: 3268 | B39: Carla Dias | C39: Standard | D39: 45385 | E39: Yes | F39: 10 | G39: Annual | H39: No | I39: - | J39: Yes | K39: 20 | L39: 10 | M39: 20 | N39: =DATE(YEAR(Tabela1[[#This Row],[Start Date]]),MONTH(Tabela1[[#This Row],[Start Date]]),1) -> 45383 | O39: =YEAR(Tabela1[[#This Row],[Start Date]]) -> 2024
A40: 3269 | B40: Diego Fontes | C40: Core | D40: 45386 | E40: No | F40: 5 | G40: Quarterly | H40: No | I40: - | J40: No | K40: 0 | L40: 1 | M40: 4 | N40: =DATE(YEAR(Tabela1[[#This Row],[Start Date]]),MONTH(Tabela1[[#This Row],[Start Date]]),1) -> 45383 | O40: =YEAR(Tabela1[[#This Row],[Start Date]]) -> 2024
...

Sheet C̳álculos
B2: ANÁLISE DE ASSINATURAS
B3: Perguntas de negócio respondidas com fórmulas dinâmicas sobre os 295 registros de 2024
B5: PERGUNTA 1 — FATURAMENTO DOS PLANOS ANUAIS
B6: Qual é o faturamento total das vendas de planos anuais, incluindo todas as assinaturas agregadas?
B7: Faturamento anual | C7: =SUMIFS(Tabela1[Total Value],Tabela1[Subscription Type],"Annual") -> 1754
B10: PERGUNTA 2 — FATURAMENTO ANUAL POR RENOVAÇÃO AUTOMÁTICA
B11: Como o faturamento dos planos anuais se divide entre clientes com e sem renovação automática?
B12: Renovação automática | C12: Faturamento anual
B13: Yes | C13: =SUMIFS(Tabela1[Total Value],Tabela1[Subscription Type],"Annual",Tabela1[Auto Renewal],B13) -> 1537
B14: No | C14: =SUMIFS(Tabela1[Total Value],Tabela1[Subscription Type],"Annual",Tabela1[Auto Renewal],B14) -> 217
B15: Total | C15: =SUM(C13:C14) -> 1754
B18: PERGUNTA 3 — VENDAS DO EA PLAY
B19: Qual é o total de vendas de assinaturas do EA Play?
B20: Indicador | C20: Resultado
B21: Quantidade de adesões | C21: =COUNTIF(Tabela1[EA Play Season Pass],"Yes") -> 98
B22: Faturamento | C22: =SUMIFS(B̳ases!I2:I296,B̳ases!H2:H296,"Yes") -> 2940
B25: PERGUNTA 4 — VENDAS DO MINECRAFT SEASON PASS
B26: Qual é o total de vendas de assinaturas do Minecraft Season Pass?
B27: Indicador | C27: Resultado
B28: Quantidade de adesões | C28: =COUNTIF(Tabela1[Minecraft Season Pass],"Yes") -> 194
B29: Faturamento | C29: =SUMIFS(Tabela1[Minecraft Season Pass Price],Tabela1[Minecraft Season Pass],"Yes") -> 3880
B32: PERGUNTA 5 — DESEMPENHO POR PLANO
B33: Quais planos geram mais assinantes e faturamento, e qual é o ticket médio de cada um?
B34: Plano | C34: Assinantes | D34: Faturamento total | E34: Ticket médio
B35: Core | C35: =COUNTIF(Tabela1[Plan],B35) -> 101 | D35: =SUMIF(Tabela1[Plan],B35,Tabela1[Total Value]) -> 444 | E35: =D35/C35 -> 4.3960396
B36: Standard | C36: =COUNTIF(Tabela1[Plan],B36) -> 96 | D36: =SUMIF(Tabela1[Plan],B36,Tabela1[Total Value]) -> 1801 | E36: =D36/C36 -> 18.760417
B37: Ultimate | C37: =COUNTIF(Tabela1[Plan],B37) -> 98 | D37: =SUMIF(Tabela1[Plan],B37,Tabela1[Total Value]) -> 5388 | E37: =D37/C37 -> 54.979592
B38: Total | C38: =SUM(C35:C37) -> 295 | D38: =SUM(D35:D37) -> 7633 | E38: =D38/C38 -> 25.874576
B41: PERGUNTA 6 — EVOLUÇÃO MENSAL
B42: Como evoluíram o faturamento total e as novas assinaturas ao longo de 2024?
B43: Mês | C43: Novas assinaturas | D43: Faturamento total
B44: =DATE(2024,1,1) -> 45292 | C44: =COUNTIFS(Tabela1[Start Date],">="&B44,Tabela1[Start Date],"<"&EDATE(B44,1)) -> 2 | D44: =SUMIFS(Tabela1[Total Value],Tabela1[Start Date],">="&B44,Tabela1[Start Date],"<"&EDATE(B44,1)) -> 65
B45: =EDATE(B44,1) -> 45323 | C45: =COUNTIFS(Tabela1[Start Date],">="&B45,Tabela1[Start Date],"<"&EDATE(B45,1)) -> 2 | D45: =SUMIFS(Tabela1[Total Value],Tabela1[Start Date],">="&B45,Tabela1[Start Date],"<"&EDATE(B45,1)) -> 82
B46: =EDATE(B45,1) -> 45352 | C46: =COUNTIFS(Tabela1[Start Date],">="&B46,Tabela1[Start Date],"<"&EDATE(B46,1)) -> 31 | D46: =SUMIFS(Tabela1[Total Value],Tabela1[Start Date],">="&B46,Tabela1[Start Date],"<"&EDATE(B46,1)) -> 801
B47: =EDATE(B46,1) -> 45383 | C47: =COUNTIFS(Tabela1[Start Date],">="&B47,Tabela1[Start Date],"<"&EDATE(B47,1)) -> 30 | D47: =SUMIFS(Tabela1[Total Value],Tabela1[Start Date],">="&B47,Tabela1[Start Date],"<"&EDATE(B47,1)) -> 782
B48: =EDATE(B47,1) -> 45413 | C48: =COUNTIFS(Tabela1[Start Date],">="&B48,Tabela1[Start Date],"<"&EDATE(B48,1)) -> 31 | D48: =SUMIFS(Tabela1[Total Value],Tabela1[Start Date],">="&B48,Tabela1[Start Date],"<"&EDATE(B48,1)) -> 777
B49: =EDATE(B48,1) -> 45444 | C49: =COUNTIFS(Tabela1[Start Date],">="&B49,Tabela1[Start Date],"<"&EDATE(B49,1)) -> 30 | D49: =SUMIFS(Tabela1[Total Value],Tabela1[Start Date],">="&B49,Tabela1[Start Date],"<"&EDATE(B49,1)) -> 770
B50: =EDATE(B49,1) -> 45474 | C50: =COUNTIFS(Tabela1[Start Date],">="&B50,Tabela1[Start Date],"<"&EDATE(B50,1)) -> 31 | D50: =SUMIFS(Tabela1[Total Value],Tabela1[Start Date],">="&B50,Tabela1[Start Date],"<"&EDATE(B50,1)) -> 784
B51: =EDATE(B50,1) -> 45505 | C51: =COUNTIFS(Tabela1[Start Date],">="&B51,Tabela1[Start Date],"<"&EDATE(B51,1)) -> 31 | D51: =SUMIFS(Tabela1[Total Value],Tabela1[Start Date],">="&B51,Tabela1[Start Date],"<"&EDATE(B51,1)) -> 787
B52: =EDATE(B51,1) -> 45536 | C52: =COUNTIFS(Tabela1[Start Date],">="&B52,Tabela1[Start Date],"<"&EDATE(B52,1)) -> 30 | D52: =SUMIFS(Tabela1[Total Value],Tabela1[Start Date],">="&B52,Tabela1[Start Date],"<"&EDATE(B52,1)) -> 780
...

Sheet D̳ashboard
F2: XBOX GAME PASS SUBSCRIPTIONS SALES
F4: Dashboard interativo de assinaturas, passes, planos e descontos | S4: ="Atualizado em "&TEXT(TODAY(),"dd/mm/aaaa") -> Atualizado em 12/09/2026
A8: FILTROS
A10: Todos os controles abaixo afetam indicadores e gráficos
A14: PERÍODO
F16: =IF('Dashboard Engine'!V21,"FATURAMENTO ANUAL","FATURAMENTO ANUAL — SEM DADOS") -> FATURAMENTO ANUAL | Q16: =IF('Dashboard Engine'!V22,"RENOVAÇÃO AUTOMÁTICA","RENOVAÇÃO AUTOMÁTICA — SEM DADOS") -> RENOVAÇÃO AUTOMÁTICA
A17: 1º semestre
A20: =TEXT('Dashboard Engine'!AH3,"mmm/aaaa")&"–"&TEXT(EDATE('Dashboard Engine'!AH4,-1),"mmm/aaaa")&CHAR(10)&"vs "&TEXT(_xlfn.XLOOKUP(A17,'Dashboard Engine'!AA2:AA8,'Dashboard Engine'!AD2:AD8),"mmm/aaaa")&"–"&TEXT(EDATE(_xlfn.XLOOKUP(A17,'Dashboard Engine'!AA2:AA8,'Dashboard Engine'!AE2:AE8),-1),"mmm/aaaa") -> jan/2024–jun/2024 vs jul/2023–dez/2023
A23: Use os filtros em conjunto para comparar segmentos
F55: =IF('Dashboard Engine'!V25,"DESEMPENHO POR PLANO","DESEMPENHO POR PLANO — SEM DADOS") -> DESEMPENHO POR PLANO | Q55: =IF('Dashboard Engine'!V26,"EVOLUÇÃO MENSAL","EVOLUÇÃO MENSAL — SEM DADOS") -> EVOLUÇÃO MENSAL

Sheet Dashboard Engine
A1: Período | B1: Data | D1: Indicador | E1: Atual | F1: Status | I1: Início atual | J1: =D̳ashboard!#REF! -> #REF! | X1: =IFERROR(GETPIVOTDATA("Soma de Total Value",'Pivot Engine'!$A$5),-1) -> 7633 | Z1: Períodos rápidos | AA1: Período | AB1: Início | AC1: Fim exclusivo | AD1: Início anterior | AE1: Fim anterior | AG1: Parâmetro | AH1: Valor
A2: Todos | D2: Receita | E2: =SUMIFS('Pivot Engine'!$G:$G,'Pivot Engine'!$A:$A,">="&$AH$3,'Pivot Engine'!$A:$A,"<"&$AH$4) -> 3277 | F2: =SUMIFS('Pivot Engine'!$G:$G,'Pivot Engine'!$A:$A,">="&_xlfn.XLOOKUP($AH$2,$AA$2:$AA$8,$AD$2:$AD$8),'Pivot Engine'!$A:$A,"<"&_xlfn.XLOOKUP($AH$2,$AA$2:$AA$8,$AE$2:$AE$8)) -> 0 | G2: =IF(OR(F2="",F2=0),"",E2/F2-1) | I2: Fim atual | J2: =EDATE(D̳ashboard!#REF!,1) -> #REF! | X2: =IFERROR(GETPIVOTDATA("Contagem de Subscriber ID",'Pivot Engine'!$A$5),-1) -> 295 | Z2: Ano completo | AA2: Ano completo | AB2: 45292 | AC2: 45658 | AD2: 44927 | AE2: 45292 | AG2: Período escolhido | AH2: =D̳ashboard!$A$17 -> 1º semestre
A3: 45292 | B3: 45292 | D3: Assinantes | E3: =SUMIFS('Pivot Engine'!$H:$H,'Pivot Engine'!$A:$A,">="&$AH$3,'Pivot Engine'!$A:$A,"<"&$AH$4) -> 126 | F3: =SUMIFS('Pivot Engine'!$H:$H,'Pivot Engine'!$A:$A,">="&_xlfn.XLOOKUP($AH$2,$AA$2:$AA$8,$AD$2:$AD$8),'Pivot Engine'!$A:$A,"<"&_xlfn.XLOOKUP($AH$2,$AA$2:$AA$8,$AE$2:$AE$8)) -> 0 | G3: =IF(OR(F3="",F3=0),"",E3/F3-1) | I3: Meses selecionados | J3: =DATEDIF(J1,J2,"m") -> #REF! | X3: =IFERROR(GETPIVOTDATA("Soma de Coupon Value",'Pivot Engine'!$A$5),-1) -> 2122 | Z3: 1º semestre | AA3: 1º semestre | AB3: 45292 | AC3: 45474 | AD3: 45108 | AE3: 45292 | AG3: Início | AH3: =_xlfn.XLOOKUP(AH2,$AA$2:$AA$8,$AB$2:$AB$8) -> 45292
A4: fev/2024 | B4: 45323 | D4: Cupons | E4: =SUMIFS('Pivot Engine'!$I:$I,'Pivot Engine'!$A:$A,">="&$AH$3,'Pivot Engine'!$A:$A,"<"&$AH$4) -> 898 | F4: =SUMIFS('Pivot Engine'!$I:$I,'Pivot Engine'!$A:$A,">="&_xlfn.XLOOKUP($AH$2,$AA$2:$AA$8,$AD$2:$AD$8),'Pivot Engine'!$A:$A,"<"&_xlfn.XLOOKUP($AH$2,$AA$2:$AA$8,$AE$2:$AE$8)) -> 0 | G4: =IF(OR(F4="",F4=0),"",E4/F4-1) | I4: Início anterior | J4: =EDATE(J1,-J3) -> #REF! | X4: =IFERROR(GETPIVOTDATA("Soma de Total Value",'Pivot Engine'!$A$5,"Plan","Core"),-1) -> -1 | Z4: 2º semestre | AA4: 2º semestre | AB4: 45474 | AC4: 45658 | AD4: 45292 | AE4: 45474 | AG4: Fim exclusivo | AH4: =_xlfn.XLOOKUP(AH2,$AA$2:$AA$8,$AC$2:$AC$8) -> 45474
A5: 45352 | B5: 45352 | D5: Renovação anual | E5: =IFERROR(SUMIFS('Pivot Engine'!$G:$G,'Pivot Engine'!$A:$A,">="&$AH$3,'Pivot Engine'!$A:$A,"<"&$AH$4,'Pivot Engine'!$D:$D,"Annual",'Pivot Engine'!$C:$C,"Yes")/SUMIFS('Pivot Engine'!$G:$G,'Pivot Engine'!$A:$A,">="&$AH$3,'Pivot Engine'!$A:$A,"<"&$AH$4,'Pivot Engine'!$D:$D,"Annual"),0) -> 0.66199377 | F5: =IFERROR(SUMIFS('Pivot Engine'!$G:$G,'Pivot Engine'!$A:$A,">="&_xlfn.XLOOKUP($AH$2,$AA$2:$AA$8,$AD$2:$AD$8),'Pivot Engine'!$A:$A,"<"&_xlfn.XLOOKUP($AH$2,$AA$2:$AA$8,$AE$2:$AE$8),'Pivot Engine'!$D:$D,"Annual",'Pivot Engine'!$C:$C,"Yes")/SUMIFS('Pivot Engine'!$G:$G,'Pivot Engine'!$A:$A,">="&_xlfn.XLOOKUP($AH$2,$AA$2:$AA$8,$AD$2:$AD$8),'Pivot Engine'!$A:$A,"<"&_xlfn.XLOOKUP($AH$2,$AA$2:$AA$8,$AE$2:$AE$8),'Pivot Engine'!$D:$D,"Annual"),"") | G5: =IF(OR(F5="",F5=0),"",E5/F5-1) | I5: Fim anterior | J5: =J1 -> #REF! | X5: =IFERROR(GETPIVOTDATA("Soma de EA Play Season Pass Price",'Pivot Engine'!$A$5),-1) -> -1 | Z5: 1º trimestre | AA5: 1º trimestre | AB5: 45292 | AC5: 45383 | AD5: 45200 | AE5: 45292 | AG5: Duração em meses | AH5: =DATEDIF(AH3,AH4,"m") -> 6
A6: abr/2024 | B6: 45383 | I6: Intervalo válido | J6: =D̳ashboard!#REF!>=D̳ashboard!#REF! -> #REF! | Z6: 2º trimestre | AA6: 2º trimestre | AB6: 45383 | AC6: 45474 | AD6: 45292 | AE6: 45383
A7: mai/2024 | B7: 45413 | Z7: 3º trimestre | AA7: 3º trimestre | AB7: 45474 | AC7: 45566 | AD7: 45383 | AE7: 45474
A8: 45444 | B8: 45444 | Z8: 4º trimestre | AA8: 4º trimestre | AB8: 45566 | AC8: 45658 | AD8: 45474 | AE8: 45566
A9: 45474 | B9: 45474
A10: ago/2024 | B10: 45505
A11: set/2024 | B11: 45536
A12: out/2024 | B12: 45566
A13: 45597 | B13: 45597
A14: dez/2024 | B14: 45627
A20: Categoria | B20: Faturamento | D20: Produto | E20: Faturamento | G20: Plano | H20: Faturamento | J20: Mês | K20: Faturamento | L20: Período selecionado | M20: Plano | N20: Cupons | O20: Líquido | P20: Bruto | R20: Renovação | S20: Valor | U20: Painel | V20: Tem dados
A21: Planos anuais | B21: =SUMIFS('Pivot Engine'!$G:$G,'Pivot Engine'!$A:$A,">="&$AH$3,'Pivot Engine'!$A:$A,"<"&$AH$4,'Pivot Engine'!$D:$D,"Annual") -> 642 | D21: EA Play | E21: =SUMIFS('Pivot Engine'!$J:$J,'Pivot Engine'!$A:$A,">="&$AH$3,'Pivot Engine'!$A:$A,"<"&$AH$4,'Pivot Engine'!$E:$E,"Yes") -> 1260 | G21: Core | H21: =SUMIFS('Pivot Engine'!$G:$G,'Pivot Engine'!$A:$A,">="&$AH$3,'Pivot Engine'!$A:$A,"<"&$AH$4,'Pivot Engine'!$B:$B,G21) -> 189 | J21: 45292 | K21: =IF(AND(J21>=$AH$3,J21<$AH$4),SUMIF('Pivot Engine'!$A:$A,J21,'Pivot Engine'!$G:$G),0) -> 65 | L21: =IF(AND(J21>=$J$1,J21<$J$2),K21,"") -> #REF! | M21: Core | N21: =SUMIFS('Pivot Engine'!$I:$I,'Pivot Engine'!$A:$A,">="&$AH$3,'Pivot Engine'!$A:$A,"<"&$AH$4,'Pivot Engine'!$B:$B,M21) -> 26 | O21: =SUMIFS('Pivot Engine'!$G:$G,'Pivot Engine'!$A:$A,">="&$AH$3,'Pivot Engine'!$A:$A,"<"&$AH$4,'Pivot Engine'!$B:$B,M21) -> 189 | P21: =N21+O21 -> 215 | R21: Yes | S21: =IF(SUM(B25:B26)=0,1,B25) -> 425 | U21: Faturamento anual | V21: =B21>0 -> TRUE
G22: Standard | H22: =SUMIFS('Pivot Engine'!$G:$G,'Pivot Engine'!$A:$A,">="&$AH$3,'Pivot Engine'!$A:$A,"<"&$AH$4,'Pivot Engine'!$B:$B,G22) -> 783 | J22: 45323 | K22: =IF(AND(J22>=$AH$3,J22<$AH$4),SUMIF('Pivot Engine'!$A:$A,J22,'Pivot Engine'!$G:$G),0) -> 82 | L22: =IF(AND(J22>=$J$1,J22<$J$2),K22,"") -> #REF! | M22: Standard | N22: =SUMIFS('Pivot Engine'!$I:$I,'Pivot Engine'!$A:$A,">="&$AH$3,'Pivot Engine'!$A:$A,"<"&$AH$4,'Pivot Engine'!$B:$B,M22) -> 447 | O22: =SUMIFS('Pivot Engine'!$G:$G,'Pivot Engine'!$A:$A,">="&$AH$3,'Pivot Engine'!$A:$A,"<"&$AH$4,'Pivot Engine'!$B:$B,M22) -> 783 | P22: =N22+O22 -> 1230 | R22: No | S22: =IF(SUM(B25:B26)=0,0,B26) -> 217 | U22: Renovação | V22: =SUM(B25:B26)>0 -> TRUE
G23: Ultimate | H23: =SUMIFS('Pivot Engine'!$G:$G,'Pivot Engine'!$A:$A,">="&$AH$3,'Pivot Engine'!$A:$A,"<"&$AH$4,'Pivot Engine'!$B:$B,G23) -> 2305 | J23: 45352 | K23: =IF(AND(J23>=$AH$3,J23<$AH$4),SUMIF('Pivot Engine'!$A:$A,J23,'Pivot Engine'!$G:$G),0) -> 801 | L23: =IF(AND(J23>=$J$1,J23<$J$2),K23,"") -> #REF! | M23: Ultimate | N23: =SUMIFS('Pivot Engine'!$I:$I,'Pivot Engine'!$A:$A,">="&$AH$3,'Pivot Engine'!$A:$A,"<"&$AH$4,'Pivot Engine'!$B:$B,M23) -> 425 | O23: =SUMIFS('Pivot Engine'!$G:$G,'Pivot Engine'!$A:$A,">="&$AH$3,'Pivot Engine'!$A:$A,"<"&$AH$4,'Pivot Engine'!$B:$B,M23) -> 2305 | P23: =N23+O23 -> 2730 | U23: EA Play | V23: =E21>0 -> TRUE
A24: Renovação | B24: Faturamento | D24: Produto | E24: Faturamento | J24: 45383 | K24: =IF(AND(J24>=$AH$3,J24<$AH$4),SUMIF('Pivot Engine'!$A:$A,J24,'Pivot Engine'!$G:$G),0) -> 782 | L24: =IF(AND(J24>=$J$1,J24<$J$2),K24,"") -> #REF! | U24: Minecraft | V24: =E25>0 -> TRUE
A25: Yes | B25: =SUMIFS('Pivot Engine'!$G:$G,'Pivot Engine'!$A:$A,">="&$AH$3,'Pivot Engine'!$A:$A,"<"&$AH$4,'Pivot Engine'!$D:$D,"Annual",'Pivot Engine'!$C:$C,A25) -> 425 | D25: Minecraft | E25: =SUMIFS('Pivot Engine'!$K:$K,'Pivot Engine'!$A:$A,">="&$AH$3,'Pivot Engine'!$A:$A,"<"&$AH$4,'Pivot Engine'!$F:$F,"Yes") -> 1660 | J25: 45413 | K25: =IF(AND(J25>=$AH$3,J25<$AH$4),SUMIF('Pivot Engine'!$A:$A,J25,'Pivot Engine'!$G:$G),0) -> 777 | L25: =IF(AND(J25>=$J$1,J25<$J$2),K25,"") -> #REF! | U25: Planos | V25: =SUM(H21:H23)>0 -> TRUE
A26: No | B26: =SUMIFS('Pivot Engine'!$G:$G,'Pivot Engine'!$A:$A,">="&$AH$3,'Pivot Engine'!$A:$A,"<"&$AH$4,'Pivot Engine'!$D:$D,"Annual",'Pivot Engine'!$C:$C,A26) -> 217 | J26: 45444 | K26: =IF(AND(J26>=$AH$3,J26<$AH$4),SUMIF('Pivot Engine'!$A:$A,J26,'Pivot Engine'!$G:$G),0) -> 770 | L26: =IF(AND(J26>=$J$1,J26<$J$2),K26,"") -> #REF! | U26: Evolução | V26: =SUM(K21:K32)>0 -> TRUE
J27: 45474 | K27: =IF(AND(J27>=$AH$3,J27<$AH$4),SUMIF('Pivot Engine'!$A:$A,J27,'Pivot Engine'!$G:$G),0) -> 0 | L27: =IF(AND(J27>=$J$1,J27<$J$2),K27,"") -> #REF! | U27: Cupons | V27: =SUM(P21:P23)>0 -> TRUE
J28: 45505 | K28: =IF(AND(J28>=$AH$3,J28<$AH$4),SUMIF('Pivot Engine'!$A:$A,J28,'Pivot Engine'!$G:$G),0) -> 0 | L28: =IF(AND(J28>=$J$1,J28<$J$2),K28,"") -> #REF!
J29: 45536 | K29: =IF(AND(J29>=$AH$3,J29<$AH$4),SUMIF('Pivot Engine'!$A:$A,J29,'Pivot Engine'!$G:$G),0) -> 0 | L29: =IF(AND(J29>=$J$1,J29<$J$2),K29,"") -> #REF!
J30: 45566 | K30: =IF(AND(J30>=$AH$3,J30<$AH$4),SUMIF('Pivot Engine'!$A:$A,J30,'Pivot Engine'!$G:$G),0) -> 0 | L30: =IF(AND(J30>=$J$1,J30<$J$2),K30,"") -> #REF!
J31: 45597 | K31: =IF(AND(J31>=$AH$3,J31<$AH$4),SUMIF('Pivot Engine'!$A:$A,J31,'Pivot Engine'!$G:$G),0) -> 0 | L31: =IF(AND(J31>=$J$1,J31<$J$2),K31,"") -> #REF!
J32: 45627 | K32: =IF(AND(J32>=$AH$3,J32<$AH$4),SUMIF('Pivot Engine'!$A:$A,J32,'Pivot Engine'!$G:$G),0) -> 0 | L32: =IF(AND(J32>=$J$1,J32<$J$2),K32,"") -> #REF!

Sheet Pivot Engine
A5: Month Start | B5: Plan | C5: Auto Renewal | D5: Subscription Type | E5: EA Play Season Pass | F5: Minecraft Season Pass | G5: Soma de Total Value | H5: Contagem de Subscriber ID | I5: Soma de Coupon Value | J5: Soma de EA Play Season Pass Price | K5: Soma de Minecraft Season Pass Price
A6: 45292 | B6: Core | C6: No | D6: Annual | E6: No | F6: No | G6: 5 | H6: 1 | I6: 0 | J6: 0 | K6: 0
A7: 45292 | B7: Ultimate | C7: Yes | D7: Monthly | E7: Yes | F7: Yes | G7: 60 | H7: 1 | I7: 5 | J7: 30 | K7: 20
A8: 45323 | B8: Standard | C8: Yes | D8: Quarterly | E8: No | F8: Yes | G8: 20 | H8: 1 | I8: 10 | J8: 0 | K8: 20
A9: 45323 | B9: Ultimate | C9: No | D9: Monthly | E9: Yes | F9: Yes | G9: 62 | H9: 1 | I9: 3 | J9: 30 | K9: 20
A10: 45352 | B10: Core | C10: No | D10: Monthly | E10: No | F10: No | G10: 19 | H10: 5 | I10: 6 | J10: 0 | K10: 0
A11: 45352 | B11: Core | C11: Yes | D11: Annual | E11: No | F11: No | G11: 15 | H11: 3 | I11: 0 | J11: 0 | K11: 0
A12: 45352 | B12: Core | C12: Yes | D12: Monthly | E12: No | F12: No | G12: 4 | H12: 1 | I12: 1 | J12: 0 | K12: 0
A13: 45352 | B13: Core | C13: Yes | D13: Quarterly | E13: No | F13: No | G13: 10 | H13: 2 | I13: 0 | J13: 0 | K13: 0
A14: 45352 | B14: Standard | C14: No | D14: Monthly | E14: No | F14: Yes | G14: 113 | H14: 5 | I14: 37 | J14: 0 | K14: 100
A15: 45352 | B15: Standard | C15: Yes | D15: Annual | E15: No | F15: Yes | G15: 33 | H15: 2 | I15: 27 | J15: 0 | K15: 40
A16: 45352 | B16: Standard | C16: Yes | D16: Quarterly | E16: No | F16: Yes | G16: 45 | H16: 3 | I16: 45 | J16: 0 | K16: 60
A17: 45352 | B17: Ultimate | C17: No | D17: Monthly | E17: Yes | F17: Yes | G17: 301 | H17: 5 | I17: 24 | J17: 150 | K17: 100
... A133: 45627 | B133: Ultimate | C133: Yes | D133: Quarterly | E133: Yes | F133: Yes | G133: 58 | H133: 1 | I133: 7 | J133: 30 | K133: 20
A134: Total Geral | G134: 7633 | H134: 295 | I134: 2122 | J134: 2940 | K134: 3880
